<?xml version="1.0" ?>

<robot name="example4">
     <link name="base_link">
        <visual>
            <origin xyz="0 0 0" rpy="0 0 0"/>
            <geometry>
                <!-- <cylinder length="0.1" radius="0.20"/> -->
                <mesh filename="model://create/meshes/create_body.dae" />    
                <!-- <mesh filename="package://robot_description/meshes/create/meshes/create_body.dae" /> -->
            </geometry>
        </visual>
        <collision>
            <origin xyz="0 0 0" rpy="0 0 0"/>
            <geometry>
                <cylinder length="0.1" radius="0.20"/>
            </geometry>
        </collision>
        <inertial>
            <mass value="10" />                                                                                                                                                      
            <inertia ixx="0.1083333" ixy = "0" ixz = "0"
                     iyy="0.1083333" iyz = "0"
                     izz="0.2" />
        </inertial>
    </link>

    <link name="left_wheel_link">
        <visual>
            <origin xyz="0 0 0" rpy="1.57 0 0"/>
            <geometry>
                <cylinder length="0.025" radius="0.06"/>
            </geometry>
        </visual>
        <collision>
            <origin xyz="0 0 0" rpy="1.57 0 0"/>
            <geometry>
                <cylinder length="0.025" radius="0.06"/>
            </geometry>
        </collision>
        <inertial>
            <mass value="2" />                                                                                                                                                      
            <inertia ixx="0.0036" ixy = "0" ixz = "0"
                     iyy="0.0036" iyz = "0"
                     izz="0.0019042" />
        </inertial>
    </link>

    <joint name="base_lefty" type="continuous">
        <origin xyz="0 0.2 -0.02" rpy="0 0 0" />
        <parent link="base_link" />
        <child link="left_wheel_link" />
        <axis xyz="0 1 0" />
    </joint>

    <link name="right_wheel_link">
        <visual>
            <origin xyz="0 0 0" rpy="1.57 0 0"/>
            <geometry>
                <cylinder length="0.025" radius="0.06"/>
            </geometry>
        </visual>
        <collision>
            <origin xyz="0 0 0" rpy="1.57 0 0"/>
            <geometry>
                <cylinder length="0.025" radius="0.06"/>
            </geometry>
        </collision>
        <inertial>
            <mass value="2" />    
            <inertia ixx="0.0036" ixy = "0" ixz = "0" 
                     iyy="0.0036" iyz = "0" 
                     izz="0.0019042" />
        </inertial>
    </link>

    <joint name="base_right" type="continuous">
        <origin xyz="0 -0.2 -0.02" rpy="0 0 0" />
        <parent link="base_link" />
        <child link="right_wheel_link" />
        <axis xyz="0 1 0" />
    </joint>

    <link name="front_caster_link">
        <visual>
            <origin xyz="0 0 0" rpy="1.57 0 0"/>
            <geometry>
                <sphere radius="0.015"/>
            </geometry>
        </visual>
        <collision>
            <origin xyz="0 0 0" rpy="1.57 0 0"/>
            <geometry>
                <sphere radius="0.015"/>
            </geometry>
        </collision>
        <inertial>
            <mass value="1" />    
            <inertia ixx="0.00015" ixy = "0" ixz = "0" 
                     iyy="0.00015" iyz = "0" 
                     izz="0.00015" />
        </inertial>
    </link>

    <joint name="front_right_joint" type="continuous">
        <origin xyz="0.18 0 -0.065" rpy="0 0 0" />
        <parent link="base_link" />
        <child link="front_caster_link" />
        <axis xyz="0 1 0" />
    </joint>

    <link name="back_caster_link">
        <visual>
            <origin xyz="0 0 0" rpy="1.57 0 0"/>
            <geometry>
                <sphere radius="0.015"/>
            </geometry>
        </visual>
        <collision>
            <origin xyz="0 0 0" rpy="1.57 0 0"/>
            <geometry>
                <sphere radius="0.015"/>
            </geometry>
        </collision>
        <inertial>
            <mass value="1" />        
            <inertia ixx="0.00015" ixy = "0" ixz = "0" 
                     iyy="0.00015" iyz = "0" 
                     izz="0.00015" />
        </inertial>
    </link>

    <joint name="back_right_joint" type="continuous">
        <origin xyz="-0.18 0 -0.065" rpy="0 0 0" />
        <parent link="base_link" />
        <child link="back_caster_link" />
        <axis xyz="0 1 0" />
    </joint>

    <link name="foot_print">
        <visual>
            <origin xyz="0 0 0" rpy="0 0 0"/>
            <geometry>
                <box size="0.01 0.01 0.01"/>
            </geometry>
        </visual>
    </link>
    <gazebo reference="foot_print">
        <turnGravityOff>false</turnGravityOff>
    </gazebo>
    <joint name="foot_print_joint" type="fixed">
        <origin xyz="0 0 0.08" rpy="0 0 0" />
        <parent link="foot_print" />
        <child link="base_link" />
    </joint>

</robot>
